<?xml version="1.0"?>
<robot xmlns:xacro="http://www.ros.org/wiki/xacro" name="my_robot"> 

    <xacro:include filename="$(find robot_description_pkg)/urdf/material.xacro"/>
    <xacro:include filename="$(find robot_description_pkg)/urdf/gazebo.xacro"/>
    
    <link name="base_link">
    </link>

    <!-- CHASSIS LINK -->
    <link name="chassis">
        <inertial>s
            <origin xyz="0.0 0.0 0.0"/>
            <mass value="1.0"/>
            <inertia ixx="0.1" ixy="0.0" ixz="0.0" iyy="0.1" iyz="0.0" izz="0.1"/>
        </inertial>
        <visual>
            <origin xyz="0.0 0.0 0.2" />
            <geometry>
                <box size="0.6 0.45 0.15"/>
            </geometry>
            <material name="white"/>
        </visual>
        <collision>
            <origin xyz="0.0 0.0 0.2" rpy="0.0 0.0 0.0"/>
            <geometry>
                <box size="0.6 0.45 0.15"/>
            </geometry>
        </collision>
    </link>
    <joint name="joint_name" type="fixed">
        <parent link="base_link"/>
        <child link="chassis"/>
    </joint>
  

    <!-- FRONT RIGHT WHEEL LINK --> 

    <link name="front_right_wheel">
        <inertial>
            <origin xyz="0.0 0.0 0.0" rpy="0.0 0.0 0.0"/>
            <mass value="0.0"/>
            <inertia ixx="0.0" ixy="0.0" ixz="0.0" iyy="0.0" iyz="0.0" izz="0.0"/>
        </inertial>
        <visual >
            <origin  rpy="0 1.5707 1.5707"/>
            <geometry>
                <cylinder radius="0.1" length="0.03"/> 
            </geometry>
            <material name="Black"/>
        </visual>
        <collision>
            <origin xrpy="0 1.5707 1.5707"/>
            <geometry>
                <cylinder radius=".1" length="0.03"/>
            </geometry>
        </collision>
    </link>

    <joint name="front_right_wheel_joint" type="continuous">
        <origin xyz="0.175 0.24 0.10" rpy="0.0 0.0 0.0"/>
        <parent link="chassis"/>
        <child link="front_right_wheel"/>
        <axis xyz="0 0 0"/>
    </joint>


    <!-- BACk RIGHT WHEEL LINK --> 
        
    <link name="back_right_wheel">
        <inertial>
            <origin rpy="0.0 0.0 0.0"/>
            <mass value="0.0"/>
            <inertia ixx="0.0" ixy="0.0" ixz="0.0" iyy="0.0" iyz="0.0" izz="0.0"/>
        </inertial>
        <visual >
            <origin  rpy="0 1.5707 1.5707"/>
            <geometry>
                <cylinder radius="0.1" length="0.03"/> 
            </geometry>
            <material name="Black"/>
        </visual>
        <collision>
            <origin  rpy="0 1.5707 1.5707"/>
            <geometry>
                <cylinder radius=".1" length="0.03"/>
            </geometry>
        </collision>
    </link>

    <joint name="back_right_wheel_joint" type="continuous">
        <origin xyz="-0.175 0.24 0.10" rpy="0.0 0.0 0.0"/>
        <parent link="chassis"/>
        <child link="back_right_wheel"/>
        <axis xyz="0 0 0"/>
    </joint>


    <!-- FRONT LEFT WHEEL LINK --> 

    <link name="front_left_wheel">
        <inertial>
            <origin xyz="0.0 0.0 0.0" rpy="0.0 0.0 0.0"/>
            <mass value="0.0"/>
            <inertia ixx="0.0" ixy="0.0" ixz="0.0" iyy="0.0" iyz="0.0" izz="0.0"/>
        </inertial>
        <visual >
            <origin  rpy="0 1.5707 1.5707"/>
            <geometry>
                <cylinder radius="0.1" length="0.03"/> 
            </geometry>
            <material name="Black"/>
        </visual>
        <collision>
            <origin rpy="0 1.5707 1.5707"/>
            <geometry>
                <cylinder radius=".1" length="0.03"/>
            </geometry>
        </collision>
    </link>

    <joint name="front_left_wheel_joint" type="continuous">
        <origin xyz="0.175 -0.24 0.10" rpy="0.0 0.0 0.0"/>
        <parent link="chassis"/>
        <child link="front_left_wheel"/>
        <axis xyz="0 0 0"/>
    </joint>


    <!-- BACK LEFT WHEEL LINK --> 

    <link name="back_left_wheel">
        <inertial>
            <origin xyz="0.0 0.0 0.0" rpy="0.0 0.0 0.0"/>
            <mass value="0.0"/>
            <inertia ixx="0.0" ixy="0.0" ixz="0.0" iyy="0.0" iyz="0.0" izz="0.0"/>
        </inertial>
        <visual >
            <origin rpy="0 1.5707 1.5707"/>
            <geometry>
                <cylinder radius="0.1" length="0.03"/> 
            </geometry>
            <material name="Black"/>
        </visual>
        <collision>
            <origin rpy="0 1.5707 1.5707"/>
            <geometry>
                <cylinder radius=".1" length="0.03"/>
            </geometry>
        </collision>
    </link>

    <joint name="back_left_wheel_joint" type="continuous">
        <origin xyz="-0.175 -0.24 0.10" rpy="0.0 0.0 0.0"/>
        <parent link="chassis"/>
        <child link="back_left_wheel"/>
        <axis xyz="0 0 0"/>
    </joint>

    <!-- CAMERA LINK -->
    <link name="camera">
        <inertial>
            <origin xyz="0.0 0.0 0.0" rpy="0.0 0.0 0.0"/>
            <mass value="0.0"/>
            <inertia ixx="0.0" ixy="0.0" ixz="0.0" iyy="0.0" iyz="0.0" izz="0.0"/>
        </inertial>
        <visual >
            <origin xyz="0.0 0.0 0.0" rpy="0.0 0.0 0.0"/>
            <geometry>
                <box size="0.050 0.20 0.07"/>
            </geometry>
            <material name="Blue"/>
        </visual>
        <collision>
            <origin xyz="0.0 0.0 0.0" rpy="0.0 0.0 0.0"/>
            <geometry>
                <box size="0.0 0.0 0.0"/>
            </geometry>
        </collision>
    </link>

    <joint name="camera_link_joint" type="fixed">
        <origin xyz="0.325 0.0 0.2" rpy="0.0 0.0 0.0"/>
        <parent link="chassis"/>
        <child link="camera"/>
        <axis xyz="0.0 0.0 0.0"/>
    </joint>
   
    <!-- LIDAR LINK -->
   
    <link name="lider">
        <inertial>
            <origin xyz="0.0 0.0 0.0" rpy="0.0 0.0 0.0"/>
            <mass value="0.0"/>
            <inertia ixx="0.0" ixy="0.0" ixz="0.0" iyy="0.0" iyz="0.0" izz="0.0"/>
        </inertial>
        <visual name="">
            <origin xyz="0.0 0.0 0.0" rpy="0.0 0.0 0.0"/>
            <geometry>
                <mesh filename="package://robot_description_pkg/meshes/hokuyo.dae"/>
            </geometry>
            <material name="Red">
        </visual>
        <collision>
            <origin xyz="0.0 0.0 0.0" rpy="0.0 0.0 0.0"/>
            <geometry>
                <mesh filename="package://robot_description_pkg/meshes/hokuyo.dae"/>
            </geometry>
        </collision>
    </link>
  
     
    <joint name="lider_joint" type="fixed">
        <origin xyz="0 0 0.304" rpy="0 0 0"/>
        <parent link="chassis"/>
        <child link="lider"/>
        <axis xyz="0 0 0" />
    </joint>

</robot>


